<?xml version="1.0"?>
<robot name="simple_spiderbot">

  <link name="base_link">
    <visual>
      <geometry>
        <box size="0.3 0.2 0.08"/>
      </geometry>
      <origin xyz="0 0 0" rpy="0 0 0"/>
    </visual>
    <collision>
      <geometry>
        <box size="0.3 0.2 0.08"/>
      </geometry>
      <origin xyz="0 0 0" rpy="0 0 0"/>
    </collision>
    <inertial>
      <mass value="1.0"/>
      <origin xyz="0 0 0" rpy="0 0 0"/>
      <inertia ixx="0.01" ixy="0" ixz="0" iyy="0.01" iyz="0" izz="0.01"/>
    </inertial>
  </link>

  <link name="leg_link_1">
    <visual>
      <geometry>
        <box size="0.05 0.05 0.2"/>
      </geometry>
      <origin xyz="0 0 -0.1" rpy="0 0 0"/>
    </visual>
    <collision>
      <geometry>
        <box size="0.05 0.05 0.2"/>
      </geometry>
      <origin xyz="0 0 -0.1" rpy="0 0 0"/>
    </collision>
    <inertial>
      <mass value="0.2"/>
      <origin xyz="0 0 -0.1" rpy="0 0 0"/>
      <inertia ixx="0.001" ixy="0" ixz="0" iyy="0.001" iyz="0" izz="0.001"/>
    </inertial>
  </link>

  <joint name="joint_1" type="revolute">
    <parent link="base_link"/>
    <child link="leg_link_1"/>
    <origin xyz="0.12 0 -0.02" rpy="0 0 0"/>
    <axis xyz="0 1 0"/>
    <limit lower="-1.57" upper="1.57" effort="5" velocity="2"/>
  </joint>

</robot>